
                        **Debug Mission** 
                        Resolve runtime crash caused by code-level incompatibilities in dependency chain.

                        **Input Context**
                        - Current environment: absl-py==1.0.0
cachetools==4.2.4
charset-normalizer==2.0.12
cycler==0.11.0
dataclasses==0.6
fsspec==2023.1.0
future==0.18.3
google-auth==1.33.1
google-auth-oauthlib==0.4.6
grpcio==1.41.0
idna==3.7
importlib-metadata==4.13.0
kiwisolver==1.4.5
Markdown==3.4.4
MarkupSafe==2.1.2
matplotlib==3.3.3
numpy==1.19.5
oauthlib==3.1.1
Pillow==9.5.0
protobuf==3.19.4
pyasn1==0.4.8
pyasn1-modules==0.2.8
pyparsing==3.0.9
python-dateutil==2.8.2
pytorch-lightning==1.4.9
PyYAML==5.4.1
requests==2.27.1
requests-oauthlib==1.3.1
rsa==4.7.2
scipy==1.5.4
six==1.16.0
tensorboard==2.5.0
tensorboard-data-server==0.6.0
tensorboard-plugin-wit==1.8.0
torch==1.10.2
tqdm==4.62.3
typing_extensions==4.0.1
urllib3==1.26.15
Werkzeug==2.0.3
zipp==3.6.0

                        - Python version: 3.7
                        - Crash traceback: Traceback (most recent call last):
  File "train.py", line 1, in <module>
    import pytorch_lightning as pl
  File "/home/lei/anaconda3/envs/py37-5/lib/python3.7/site-packages/pytorch_lightning/__init__.py", line 20, in <module>
    from pytorch_lightning import metrics  # noqa: E402
  File "/home/lei/anaconda3/envs/py37-5/lib/python3.7/site-packages/pytorch_lightning/metrics/__init__.py", line 15, in <module>
    from pytorch_lightning.metrics.classification import (  # noqa: F401
  File "/home/lei/anaconda3/envs/py37-5/lib/python3.7/site-packages/pytorch_lightning/metrics/classification/__init__.py", line 14, in <module>
    from pytorch_lightning.metrics.classification.accuracy import Accuracy  # noqa: F401
  File "/home/lei/anaconda3/envs/py37-5/lib/python3.7/site-packages/pytorch_lightning/metrics/classification/accuracy.py", line 18, in <module>
    from pytorch_lightning.metrics.utils import deprecated_metrics, void
  File "/home/lei/anaconda3/envs/py37-5/lib/python3.7/site-packages/pytorch_lightning/metrics/utils.py", line 22, in <module>
    from torchmetrics.utilities.data import get_num_classes as _get_num_classes
ImportError: cannot import name 'get_num_classes' from 'torchmetrics.utilities.data' (/home/lei/anaconda3/envs/py37-5/lib/python3.7/site-packages/torchmetrics/utilities/data.py)


                        **Analysis Protocol**
                        1. Traceback Pattern Matching：
                        a. Identify error type (ImportError/AttributeError/TypeError)
                        b. Map to possible API changes in torch v1.10.2 or its dependencies
                        2. Compatibility Matrix Check：
                        a. Verify library-to-library API compatibility through version ranges
                        b. Confirm project-to-library interface compatibility
                        3. Breakpoint Isolation：
                        b. Determine if conflict originates from：
                            • Direct API changes in torch
                            • Transitive dependency API shifts

                        **Resolution Rules**
                        - PRIMARY CONSTRAINT: Maintain torch==1.10.2
                        - SECONDARY ADJUSTMENTS: 
                        • Modify dependency versions only when API contracts allow
                        • Prefer backward-compatible minor version changes

                        **Output Mandates**
                        STRICT FORMAT:
                        lib1==x.y.z  
                        lib2==a.b.c
                        ...
                        PROHIBITED:
                        • Any non-version text.
                        • Library additions/removals
                        • Version placeholders
                        MANDATORY:
                        • Preserve original library names and count
                        • Pin EXACT versions
                        • Zero explanations/comments
                        