Start to train.
Traceback (most recent call last):
  File "train.py", line 152, in <module>
    main()
  File "train.py", line 101, in main
    classification_loss, bbox_regression_loss,ldm_regression_loss = retinaface([data['img'].cuda().float(), data['annot']])
  File "/home/lei/anaconda3/envs/py37-1/lib/python3.7/site-packages/torch/nn/modules/module.py", line 889, in _call_impl
    result = self.forward(*input, **kwargs)
  File "/home/lei/anaconda3/envs/py37-1/lib/python3.7/site-packages/torch/nn/parallel/data_parallel.py", line 167, in forward
    outputs = self.parallel_apply(replicas, inputs, kwargs)
  File "/home/lei/anaconda3/envs/py37-1/lib/python3.7/site-packages/torch/nn/parallel/data_parallel.py", line 177, in parallel_apply
    return parallel_apply(replicas, inputs, kwargs, self.device_ids[:len(replicas)])
  File "/home/lei/anaconda3/envs/py37-1/lib/python3.7/site-packages/torch/nn/parallel/parallel_apply.py", line 86, in parallel_apply
    output.reraise()
  File "/home/lei/anaconda3/envs/py37-1/lib/python3.7/site-packages/torch/_utils.py", line 429, in reraise
    raise self.exc_type(msg)
RuntimeError: Caught RuntimeError in replica 0 on device 0.
Original Traceback (most recent call last):
  File "/home/lei/anaconda3/envs/py37-1/lib/python3.7/site-packages/torch/nn/parallel/parallel_apply.py", line 61, in _worker
    output = module(*input, **kwargs)
  File "/home/lei/anaconda3/envs/py37-1/lib/python3.7/site-packages/torch/nn/modules/module.py", line 889, in _call_impl
    result = self.forward(*input, **kwargs)
  File "/home/lei/compatibility_analysis/pytorch/1.1/RetinaFace_Pytorch/torchvision_model.py", line 204, in forward
    out = self.body(img_batch)
  File "/home/lei/anaconda3/envs/py37-1/lib/python3.7/site-packages/torch/nn/modules/module.py", line 889, in _call_impl
    result = self.forward(*input, **kwargs)
  File "/home/lei/anaconda3/envs/py37-1/lib/python3.7/site-packages/torchvision/models/_utils.py", line 63, in forward
    x = module(x)
  File "/home/lei/anaconda3/envs/py37-1/lib/python3.7/site-packages/torch/nn/modules/module.py", line 889, in _call_impl
    result = self.forward(*input, **kwargs)
  File "/home/lei/anaconda3/envs/py37-1/lib/python3.7/site-packages/torch/nn/modules/conv.py", line 399, in forward
    return self._conv_forward(input, self.weight, self.bias)
  File "/home/lei/anaconda3/envs/py37-1/lib/python3.7/site-packages/torch/nn/modules/conv.py", line 396, in _conv_forward
    self.padding, self.dilation, self.groups)
RuntimeError: cuDNN error: CUDNN_STATUS_NOT_INITIALIZED

