
                        **Debug Mission** 
                        Resolve runtime crash caused by code-level incompatibilities in dependency chain.

                        **Input Context**
                        - Current environment: blis==0.7.11
catalogue==2.0.10
charset-normalizer==3.3.2
click==7.1.2
coloredlogs==15.0.1
cymem==2.0.8
filelock==3.12.2
humanfriendly==10.0
idna==3.7
importlib-metadata==4.13.0
Jinja2==2.11.3
joblib==1.3.2
MarkupSafe==2.1.5
mpmath==1.2.1
murmurhash==1.0.10
numpy==1.21.1
packaging==20.9
pathy==0.10.3
preshed==3.0.9
protobuf==3.20.3
pydantic==1.7.4
regex==2024.4.16
requests==2.31.0
sacremoses==0.0.53
scikit-learn==0.24.2
scipy==1.7.3
sentencepiece==0.1.91
six==1.16.0
smart-open==6.4.0
spacy==3.0.6
spacy-legacy==3.0.12
srsly==2.4.8
sympy==1.10.1
tensorboardX==1.6
thinc==8.0.17
threadpoolctl==3.1.0
tokenizers==0.10.3
torch==1.4.0
tqdm==4.55.1
transformers==4.5.1
typer==0.3.2
typing_extensions==3.7.4.3
urllib3==1.26.15
wasabi==0.10.1
zipp==3.15.0

                        - Python version: 3.7
                        - Crash traceback: Traceback (most recent call last):
  File "/home/lei/anaconda3/envs/py37-4/lib/python3.7/multiprocessing/process.py", line 297, in _bootstrap
    self.run()
  File "/home/lei/anaconda3/envs/py37-4/lib/python3.7/multiprocessing/process.py", line 99, in run
    self._target(*self._args, **self._kwargs)
  File "/home/lei/compatibility_analysis/pytorch/1.4/spert/spert.py", line 15, in __train
    trainer = SpERTTrainer(run_args)
  File "/home/lei/compatibility_analysis/pytorch/1.4/spert/spert/spert_trainer.py", line 36, in __init__
    cache_dir=args.cache_path)
  File "/home/lei/anaconda3/envs/py37-4/lib/python3.7/site-packages/transformers/tokenization_utils_base.py", line 1670, in from_pretrained
    user_agent=user_agent,
  File "/home/lei/anaconda3/envs/py37-4/lib/python3.7/site-packages/transformers/file_utils.py", line 1173, in cached_path
    local_files_only=local_files_only,
  File "/home/lei/anaconda3/envs/py37-4/lib/python3.7/site-packages/transformers/file_utils.py", line 1389, in get_from_cache
    "Connection error, and we cannot find the requested files in the cached path."
ValueError: Connection error, and we cannot find the requested files in the cached path. Please try again or make sure your Internet connection is on.


                        **Analysis Protocol**
                        1. Traceback Pattern Matching：
                        a. Identify error type (ImportError/AttributeError/TypeError)
                        b. Map to possible API changes in numpy v1.21.1 or its dependencies
                        2. Compatibility Matrix Check：
                        a. Verify library-to-library API compatibility through version ranges
                        b. Confirm project-to-library interface compatibility
                        3. Breakpoint Isolation：
                        b. Determine if conflict originates from：
                            • Direct API changes in numpy
                            • Transitive dependency API shifts

                        **Resolution Rules**
                        - PRIMARY CONSTRAINT: Maintain numpy==1.21.1
                        - SECONDARY ADJUSTMENTS: 
                        • Modify dependency versions only when API contracts allow
                        • Prefer backward-compatible minor version changes

                        **Output Mandates**
                        STRICT FORMAT:
                        lib1==x.y.z  
                        lib2==a.b.c
                        ...
                        PROHIBITED:
                        • Any non-version text.
                        • Library additions/removals
                        • Version placeholders
                        MANDATORY:
                        • Preserve original library names and count
                        • Pin EXACT versions
                        • Zero explanations/comments
                        