
                        **Debug Mission** 
                        Resolve runtime crash caused by code-level incompatibilities in dependency chain.

                        **Input Context**
                        - Current environment: absl-py==2.1.0
cachetools==5.4.0
charset-normalizer==3.3.2
cycler==0.11.0
dataclasses==0.6
fsspec==2023.1.0
future==1.0.0
google-auth==2.32.0
google-auth-oauthlib==0.4.6
grpcio==1.39.0
idna==3.7
importlib-metadata==6.7.0
kiwisolver==1.4.5
Markdown==3.4.4
MarkupSafe==2.1.5
matplotlib==3.4.3
numpy==1.21.1
oauthlib==3.2.2
Pillow==9.5.0
protobuf==3.20.3
pyasn1==0.5.1
pyasn1-modules==0.3.0
pyparsing==3.1.2
python-dateutil==2.8.2
pytorch-lightning==1.1.0
PyYAML==6.0.1
requests==2.31.0
requests-oauthlib==2.0.0
rsa==4.9
scipy==1.7.3
six==1.16.0
tensorboard==2.11.2
tensorboard-data-server==0.6.1
tensorboard-plugin-wit==1.8.1
torch==1.8.0
tqdm==4.66.4
typing_extensions==4.7.1
urllib3==2.0.7
Werkzeug==2.2.3
zipp==3.15.0

                        - Python version: 3.7
                        - Crash traceback: Traceback (most recent call last):
  File "train.py", line 56, in <module>
    main(args)
  File "train.py", line 30, in main
    trainer.fit(model)
  File "/home/lei/anaconda3/envs/py37-5/lib/python3.7/site-packages/pytorch_lightning/trainer/trainer.py", line 470, in fit
    results = self.accelerator_backend.train()
  File "/home/lei/anaconda3/envs/py37-5/lib/python3.7/site-packages/pytorch_lightning/accelerators/gpu_accelerator.py", line 66, in train
    results = self.train_or_test()
  File "/home/lei/anaconda3/envs/py37-5/lib/python3.7/site-packages/pytorch_lightning/accelerators/accelerator.py", line 65, in train_or_test
    results = self.trainer.train()
  File "/home/lei/anaconda3/envs/py37-5/lib/python3.7/site-packages/pytorch_lightning/trainer/trainer.py", line 492, in train
    self.run_sanity_check(self.get_model())
  File "/home/lei/anaconda3/envs/py37-5/lib/python3.7/site-packages/pytorch_lightning/trainer/trainer.py", line 690, in run_sanity_check
    _, eval_results = self.run_evaluation(test_mode=False, max_batches=self.num_sanity_val_batches)
  File "/home/lei/anaconda3/envs/py37-5/lib/python3.7/site-packages/pytorch_lightning/trainer/trainer.py", line 606, in run_evaluation
    output = self.evaluation_loop.evaluation_step(test_mode, batch, batch_idx, dataloader_idx)
  File "/home/lei/anaconda3/envs/py37-5/lib/python3.7/site-packages/pytorch_lightning/trainer/evaluation_loop.py", line 178, in evaluation_step
    output = self.trainer.accelerator_backend.validation_step(args)
  File "/home/lei/anaconda3/envs/py37-5/lib/python3.7/site-packages/pytorch_lightning/accelerators/gpu_accelerator.py", line 84, in validation_step
    return self._step(self.trainer.model.validation_step, args)
  File "/home/lei/anaconda3/envs/py37-5/lib/python3.7/site-packages/pytorch_lightning/accelerators/gpu_accelerator.py", line 76, in _step
    output = model_step(*args)
  File "/home/lei/compatibility_analysis/pytorch/1.7/PedalNetRT/model.py", line 152, in validation_step
    y_pred = self.forward(x)
  File "/home/lei/compatibility_analysis/pytorch/1.7/PedalNetRT/model.py", line 141, in forward
    return self.wavenet(x)
  File "/home/lei/anaconda3/envs/py37-5/lib/python3.7/site-packages/torch/nn/modules/module.py", line 889, in _call_impl
    result = self.forward(*input, **kwargs)
  File "/home/lei/compatibility_analysis/pytorch/1.7/PedalNetRT/model.py", line 74, in forward
    out = self.input_layer(out)
  File "/home/lei/anaconda3/envs/py37-5/lib/python3.7/site-packages/torch/nn/modules/module.py", line 889, in _call_impl
    result = self.forward(*input, **kwargs)
  File "/home/lei/compatibility_analysis/pytorch/1.7/PedalNetRT/model.py", line 27, in forward
    result = super(CausalConv1d, self).forward(input)
  File "/home/lei/anaconda3/envs/py37-5/lib/python3.7/site-packages/torch/nn/modules/conv.py", line 263, in forward
    return self._conv_forward(input, self.weight, self.bias)
  File "/home/lei/anaconda3/envs/py37-5/lib/python3.7/site-packages/torch/nn/modules/conv.py", line 260, in _conv_forward
    self.padding, self.dilation, self.groups)
RuntimeError: cuDNN error: CUDNN_STATUS_NOT_INITIALIZED

                                           


                        **Analysis Protocol**
                        1. Traceback Pattern Matching：
                        a. Identify error type (ImportError/AttributeError/TypeError)
                        b. Map to possible API changes in numpy v1.21.1 or its dependencies
                        2. Compatibility Matrix Check：
                        a. Verify library-to-library API compatibility through version ranges
                        b. Confirm project-to-library interface compatibility
                        3. Breakpoint Isolation：
                        b. Determine if conflict originates from：
                            • Direct API changes in numpy
                            • Transitive dependency API shifts

                        **Resolution Rules**
                        - PRIMARY CONSTRAINT: Maintain numpy==1.21.1
                        - SECONDARY ADJUSTMENTS: 
                        • Modify dependency versions only when API contracts allow
                        • Prefer backward-compatible minor version changes

                        **Output Mandates**
                        STRICT FORMAT:
                        lib1==x.y.z  
                        lib2==a.b.c
                        ...
                        PROHIBITED:
                        • Any non-version text.
                        • Library additions/removals
                        • Version placeholders
                        MANDATORY:
                        • Preserve original library names and count
                        • Pin EXACT versions
                        • Zero explanations/comments
                        