Traceback (most recent call last):
  File "run.py", line 146, in <module>
    tenOutput = estimate(tenInput)
  File "run.py", line 138, in estimate
    return netNetwork(tenInput.cuda().view(1, 3, intHeight, intWidth))[0, :, :, :].cpu()
  File "/home/lei/anaconda3/envs/py37-4/lib/python3.7/site-packages/torch/nn/modules/module.py", line 889, in _call_impl
    result = self.forward(*input, **kwargs)
  File "run.py", line 99, in forward
    tenVggOne = self.netVggOne(tenInput)
  File "/home/lei/anaconda3/envs/py37-4/lib/python3.7/site-packages/torch/nn/modules/module.py", line 889, in _call_impl
    result = self.forward(*input, **kwargs)
  File "/home/lei/anaconda3/envs/py37-4/lib/python3.7/site-packages/torch/nn/modules/container.py", line 119, in forward
    input = module(input)
  File "/home/lei/anaconda3/envs/py37-4/lib/python3.7/site-packages/torch/nn/modules/module.py", line 889, in _call_impl
    result = self.forward(*input, **kwargs)
  File "/home/lei/anaconda3/envs/py37-4/lib/python3.7/site-packages/torch/nn/modules/conv.py", line 399, in forward
    return self._conv_forward(input, self.weight, self.bias)
  File "/home/lei/anaconda3/envs/py37-4/lib/python3.7/site-packages/torch/nn/modules/conv.py", line 396, in _conv_forward
    self.padding, self.dilation, self.groups)
RuntimeError: cuDNN error: CUDNN_STATUS_NOT_INITIALIZED
