
                        **Debug Mission** 
                        Resolve runtime crash caused by code-level incompatibilities in dependency chain.

                        **Input Context**
                        - Current environment: absl-py==2.1.0
cachetools==4.2.4
charset-normalizer==3.3.2
cycler==0.10.0
dataclasses==0.6
fsspec==2021.7.0
future==1.0.0
google-auth==1.33.1
google-auth-oauthlib==0.4.1
grpcio==1.41.1
idna==2.10
importlib-metadata==4.8.1
kiwisolver==1.3.1
Markdown==3.3.4
MarkupSafe==2.0.1
matplotlib==3.4.3
numpy==1.20.2
oauthlib==3.1.0
Pillow==8.2.0
protobuf==3.17.3
pyasn1==0.4.8
pyasn1-modules==0.2.8
pyparsing==2.4.7
python-dateutil==2.8.1
pytorch-lightning==1.3.7
PyYAML==5.4.1
requests==2.25.1
requests-oauthlib==1.3.0
rsa==4.5
scipy==1.6.2
six==1.16.0
tensorboard==2.4.0
tensorboard-data-server==0.6.0
tensorboard-plugin-wit==1.7.0
torch==1.8.1
tqdm==4.59.0
urllib3==1.26.5
Werkzeug==2.0.1
zipp==3.5.0

                        - Python version: 3.7
                        - Crash traceback: Traceback (most recent call last):
  File "train.py", line 1, in <module>
    import pytorch_lightning as pl
  File "/home/lei/anaconda3/envs/py37-5/lib/python3.7/site-packages/pytorch_lightning/__init__.py", line 20, in <module>
    from pytorch_lightning import metrics  # noqa: E402
  File "/home/lei/anaconda3/envs/py37-5/lib/python3.7/site-packages/pytorch_lightning/metrics/__init__.py", line 15, in <module>
    from pytorch_lightning.metrics.classification import (  # noqa: F401
  File "/home/lei/anaconda3/envs/py37-5/lib/python3.7/site-packages/pytorch_lightning/metrics/classification/__init__.py", line 14, in <module>
    from pytorch_lightning.metrics.classification.accuracy import Accuracy  # noqa: F401
  File "/home/lei/anaconda3/envs/py37-5/lib/python3.7/site-packages/pytorch_lightning/metrics/classification/accuracy.py", line 18, in <module>
    from pytorch_lightning.metrics.utils import deprecated_metrics
  File "/home/lei/anaconda3/envs/py37-5/lib/python3.7/site-packages/pytorch_lightning/metrics/utils.py", line 22, in <module>
    from torchmetrics.utilities.data import get_num_classes as _get_num_classes
ImportError: cannot import name 'get_num_classes' from 'torchmetrics.utilities.data' (/home/lei/anaconda3/envs/py37-5/lib/python3.7/site-packages/torchmetrics/utilities/data.py)


                        **Analysis Protocol**
                        1. Traceback Pattern Matching：
                        a. Identify error type (ImportError/AttributeError/TypeError)
                        b. Map to possible API changes in pytorch-lightning v1.3.7 or its dependencies
                        2. Compatibility Matrix Check：
                        a. Verify library-to-library API compatibility through version ranges
                        b. Confirm project-to-library interface compatibility
                        3. Breakpoint Isolation：
                        b. Determine if conflict originates from：
                            • Direct API changes in pytorch-lightning
                            • Transitive dependency API shifts

                        **Resolution Rules**
                        - PRIMARY CONSTRAINT: Maintain pytorch-lightning==1.3.7
                        - SECONDARY ADJUSTMENTS: 
                        • Modify dependency versions only when API contracts allow
                        • Prefer backward-compatible minor version changes

                        **Output Mandates**
                        STRICT FORMAT:
                        lib1==x.y.z  
                        lib2==a.b.c
                        ...
                        PROHIBITED:
                        • Any non-version text.
                        • Library additions/removals
                        • Version placeholders
                        MANDATORY:
                        • Preserve original library names and count
                        • Pin EXACT versions
                        • Zero explanations/comments
                        